Workbook

Sheet README
A3: How this version works

Sheet Dashboard
A1: 冷水机组 Delivery Dashboard
A3: Master dashboard linked to Product_Registry, Project_Tracker, Logic & Lists, and BOM_Tracker.
A5: Selected Tag | C5: Description | E5: Customer | G5: Product Type | I5: ROS | K5: Production Start | M5: Components PO Plan | O5: Days to ROS | Q5: Urgent BOM Items | S5: Project Manager | U5: Overall Status
A6: 123456 | C6: =IFERROR(INDEX(Project_Tracker!$B$2:$B$101,MATCH($A$6,Project_Tracker!$AL$2:$AL$101,0)),"") -> Chiller Water Unit | E6: =IFERROR(INDEX(Project_Tracker!$D$2:$D$101,MATCH($A$6,Project_Tracker!$AL$2:$AL$101,0)),"") -> Sample Customer | G6: =IFERROR(INDEX(Project_Tracker!$C$2:$C$101,MATCH($A$6,Project_Tracker!$AL$2:$AL$101,0)),"") -> 冷水机组 | I6: =IFERROR(INDEX(Project_Tracker!$F$2:$F$101,MATCH($A$6,Project_Tracker!$AL$2:$AL$101,0)),"") -> 46315 | K6: =IFERROR(INDEX(Project_Tracker!$T$2:$T$101,MATCH($A$6,Project_Tracker!$AL$2:$AL$101,0)),"") -> 46244 | M6: =IFERROR(INDEX(Project_Tracker!$S$2:$S$101,MATCH($A$6,Project_Tracker!$AL$2:$AL$101,0)),"") -> 46104 | O6: =IFERROR(INDEX(Project_Tracker!$AI$2:$AI$101,MATCH($A$6,Project_Tracker!$AL$2:$AL$101,0)),"") -> 63 | Q6: =COUNTIFS(BOM_Tracker!$A$6:$A$1705,$A$6,BOM_Tracker!$J$6:$J$1705,"URGENT")+COUNTIFS(BOM_Tracker!$A$6:$A$1705,$A$6,BOM_Tracker!$J$6:$J$1705,"OVERDUE") -> 17 | S6: =IFERROR(VLOOKUP($A$6,Project_Tracker!$A$2:$AJ$101,9,FALSE),"") -> PM Owner | U6: =IFERROR(VLOOKUP($A$6,Project_Tracker!$A$2:$AJ$101,34,FALSE),"") -> On Track
A9: Phase status table | G9: Program Timeline / Daily Phase Gantt
A10: Phase | B10: Plan Start | C10: Plan Finish | D10: Reference | E10: Status | G10: =IF(G11="","",IF(DAY(G11)=1,TEXT(G11,"mmm"),"")) -> Feb | H10: =IF(H11="","",IF(DAY(H11)=1,TEXT(H11,"mmm"),"")) | I10: =IF(I11="","",IF(DAY(I11)=1,TEXT(I11,"mmm"),"")) | J10: =IF(J11="","",IF(DAY(J11)=1,TEXT(J11,"mmm"),"")) | K10: =IF(K11="","",IF(DAY(K11)=1,TEXT(K11,"mmm"),"")) | L10: =IF(L11="","",IF(DAY(L11)=1,TEXT(L11,"mmm"),"")) | M10: =IF(M11="","",IF(DAY(M11)=1,TEXT(M11,"mmm"),"")) | N10: =IF(N11="","",IF(DAY(N11)=1,TEXT(N11,"mmm"),"")) | ... JP10: =IF(JP11="","",IF(DAY(JP11)=1,TEXT(JP11,"mmm"),""))
G11: =IF($A$6="","",DATE(YEAR(MIN($B$12:$B$21)),MONTH(MIN($B$12:$B$21)),1)) -> 46054 | H11: =IF(G11="","",G11+1) -> 46055 | I11: =IF(H11="","",H11+1) -> 46056 | J11: =IF(I11="","",I11+1) -> 46057 | K11: =IF(J11="","",J11+1) -> 46058 | L11: =IF(K11="","",K11+1) -> 46059 | M11: =IF(L11="","",L11+1) -> 46060 | N11: =IF(M11="","",M11+1) -> 46061 | O11: =IF(N11="","",N11+1) -> 46062 | ... JP11: =IF(JO11="","",JO11+1) -> 46323
A12: Contract / Kickoff | B12: =IF($B$32="","",$B$32) -> 46091 | C12: =IF($B$33="","",$B$33) -> 46119 | D12: =IFERROR(INDEX(Project_Tracker!$G$2:$G$101,MATCH($A$6,Project_Tracker!$AL$2:$AL$101,0)),"") -> CN-2026-001 | E12: =IF($C12="","",IF(TODAY()>$C12,"Done",IF(TODAY()<$B12,"Planned","Current"))) -> Done | G12: =IF(G$11="","",IF(AND(G$11>=$B12,G$11<=$C12),1,"")) | H12: =IF(H$11="","",IF(AND(H$11>=$B12,H$11<=$C12),1,"")) | I12: =IF(I$11="","",IF(AND(I$11>=$B12,I$11<=$C12),1,"")) | J12: =IF(J$11="","",IF(AND(J$11>=$B12,J$11<=$C12),1,"")) | K12: =IF(K$11="","",IF(AND(K$11>=$B12,K$11<=$C12),1,"")) | L12: =IF(L$11="","",IF(AND(L$11>=$B12,L$11<=$C12),1,"")) | M12: =IF(M$11="","",IF(AND(M$11>=$B12,M$11<=$C12),1,"")) | N12: =IF(N$11="","",IF(AND(N$11>=$B12,N$11<=$C12),1,"")) | ... JP12: =IF(JP$11="","",IF(AND(JP$11>=$B12,JP$11<=$C12),1,""))
A13: Drawing Freeze | B13: =IF(COUNT($B$34,$B$35)=0,"",MIN($B$34,$B$35)) -> 46074 | C13: =IF(COUNT($B$34,$B$35)=0,"",MAX($B$34,$B$35)) -> 46094 | D13: Input Frozen → Drawing Approval | E13: =IF($C13="","",IF(TODAY()>$C13,"Done",IF(TODAY()<$B13,"Planned","Current"))) -> Done | G13: =IF(G$11="","",IF(AND(G$11>=$B13,G$11<=$C13),1,"")) | H13: =IF(H$11="","",IF(AND(H$11>=$B13,H$11<=$C13),1,"")) | I13: =IF(I$11="","",IF(AND(I$11>=$B13,I$11<=$C13),1,"")) | J13: =IF(J$11="","",IF(AND(J$11>=$B13,J$11<=$C13),1,"")) | K13: =IF(K$11="","",IF(AND(K$11>=$B13,K$11<=$C13),1,"")) | L13: =IF(L$11="","",IF(AND(L$11>=$B13,L$11<=$C13),1,"")) | M13: =IF(M$11="","",IF(AND(M$11>=$B13,M$11<=$C13),1,"")) | N13: =IF(N$11="","",IF(AND(N$11>=$B13,N$11<=$C13),1,"")) | ... JP13: =IF(JP$11="","",IF(AND(JP$11>=$B13,JP$11<=$C13),1,""))
A14: BOM Release | B14: =IF(COUNT($B$35,$B$36)=0,"",MIN($B$35,$B$36)) -> 46094 | C14: =IF(COUNT($B$35,$B$36)=0,"",MAX($B$35,$B$36)) -> 46101 | D14: Drawing Approval → BOM Pass | E14: =IF($C14="","",IF(TODAY()>$C14,"Done",IF(TODAY()<$B14,"Planned","Current"))) -> Done | G14: =IF(G$11="","",IF(AND(G$11>=$B14,G$11<=$C14),1,"")) | H14: =IF(H$11="","",IF(AND(H$11>=$B14,H$11<=$C14),1,"")) | I14: =IF(I$11="","",IF(AND(I$11>=$B14,I$11<=$C14),1,"")) | J14: =IF(J$11="","",IF(AND(J$11>=$B14,J$11<=$C14),1,"")) | K14: =IF(K$11="","",IF(AND(K$11>=$B14,K$11<=$C14),1,"")) | L14: =IF(L$11="","",IF(AND(L$11>=$B14,L$11<=$C14),1,"")) | M14: =IF(M$11="","",IF(AND(M$11>=$B14,M$11<=$C14),1,"")) | N14: =IF(N$11="","",IF(AND(N$11>=$B14,N$11<=$C14),1,"")) | ... JP14: =IF(JP$11="","",IF(AND(JP$11>=$B14,JP$11<=$C14),1,""))
A15: PR / PO Planning | B15: =IF(COUNT($B$37,$B$38)=0,"",MIN($B$37,$B$38)) -> 46097 | C15: =IF(COUNT($B$37,$B$38)=0,"",MAX($B$37,$B$38)) -> 46104 | D15: PR Schedule → Components PO Plan | E15: =IF($C15="","",IF(TODAY()>$C15,"Done",IF(TODAY()<$B15,"Planned","Current"))) -> Done | G15: =IF(G$11="","",IF(AND(G$11>=$B15,G$11<=$C15),1,"")) | H15: =IF(H$11="","",IF(AND(H$11>=$B15,H$11<=$C15),1,"")) | I15: =IF(I$11="","",IF(AND(I$11>=$B15,I$11<=$C15),1,"")) | J15: =IF(J$11="","",IF(AND(J$11>=$B15,J$11<=$C15),1,"")) | K15: =IF(K$11="","",IF(AND(K$11>=$B15,K$11<=$C15),1,"")) | L15: =IF(L$11="","",IF(AND(L$11>=$B15,L$11<=$C15),1,"")) | M15: =IF(M$11="","",IF(AND(M$11>=$B15,M$11<=$C15),1,"")) | N15: =IF(N$11="","",IF(AND(N$11>=$B15,N$11<=$C15),1,"")) | ... JP15: =IF(JP$11="","",IF(AND(JP$11>=$B15,JP$11<=$C15),1,""))
A16: Material Lead Time | B16: =IF($B$38="","",$B$38) -> 46104 | C16: =IF($B$39="","",$B$39) -> 46244 | D16: Components PO Plan → Production Start | E16: =IF($C16="","",IF(TODAY()>$C16,"Done",IF(TODAY()<$B16,"Planned","Current"))) -> Done | G16: =IF(G$11="","",IF(AND(G$11>=$B16,G$11<=$C16),1,"")) | H16: =IF(H$11="","",IF(AND(H$11>=$B16,H$11<=$C16),1,"")) | I16: =IF(I$11="","",IF(AND(I$11>=$B16,I$11<=$C16),1,"")) | J16: =IF(J$11="","",IF(AND(J$11>=$B16,J$11<=$C16),1,"")) | K16: =IF(K$11="","",IF(AND(K$11>=$B16,K$11<=$C16),1,"")) | L16: =IF(L$11="","",IF(AND(L$11>=$B16,L$11<=$C16),1,"")) | M16: =IF(M$11="","",IF(AND(M$11>=$B16,M$11<=$C16),1,"")) | N16: =IF(N$11="","",IF(AND(N$11>=$B16,N$11<=$C16),1,"")) | ... JP16: =IF(JP$11="","",IF(AND(JP$11>=$B16,JP$11<=$C16),1,""))
A17: Production | B17: =IF($B$39="","",$B$39) -> 46244 | C17: =IF($B$40="","",$B$40) -> 46289 | D17: Production Start → Complete | E17: =IF($C17="","",IF(TODAY()>$C17,"Done",IF(TODAY()<$B17,"Planned","Current"))) -> Current | G17: =IF(G$11="","",IF(AND(G$11>=$B17,G$11<=$C17),1,"")) | H17: =IF(H$11="","",IF(AND(H$11>=$B17,H$11<=$C17),1,"")) | I17: =IF(I$11="","",IF(AND(I$11>=$B17,I$11<=$C17),1,"")) | J17: =IF(J$11="","",IF(AND(J$11>=$B17,J$11<=$C17),1,"")) | K17: =IF(K$11="","",IF(AND(K$11>=$B17,K$11<=$C17),1,"")) | L17: =IF(L$11="","",IF(AND(L$11>=$B17,L$11<=$C17),1,"")) | M17: =IF(M$11="","",IF(AND(M$11>=$B17,M$11<=$C17),1,"")) | N17: =IF(N$11="","",IF(AND(N$11>=$B17,N$11<=$C17),1,"")) | ... JP17: =IF(JP$11="","",IF(AND(JP$11>=$B17,JP$11<=$C17),1,""))
A18: NOI / Docs | B18: =IF(COUNT($B$41,$B$44)=0,"",MIN($B$41,$B$44)) -> 46269 | C18: =IF(COUNT($B$41,$B$44)=0,"",MAX($B$41,$B$44)) -> 46297 | D18: NOI Date → FAT Start | E18: =IF($C18="","",IF(TODAY()>$C18,"Done",IF(TODAY()<$B18,"Planned","Current"))) -> Planned | G18: =IF(G$11="","",IF(AND(G$11>=$B18,G$11<=$C18),1,"")) | H18: =IF(H$11="","",IF(AND(H$11>=$B18,H$11<=$C18),1,"")) | I18: =IF(I$11="","",IF(AND(I$11>=$B18,I$11<=$C18),1,"")) | J18: =IF(J$11="","",IF(AND(J$11>=$B18,J$11<=$C18),1,"")) | K18: =IF(K$11="","",IF(AND(K$11>=$B18,K$11<=$C18),1,"")) | L18: =IF(L$11="","",IF(AND(L$11>=$B18,L$11<=$C18),1,"")) | M18: =IF(M$11="","",IF(AND(M$11>=$B18,M$11<=$C18),1,"")) | N18: =IF(N$11="","",IF(AND(N$11>=$B18,N$11<=$C18),1,"")) | ... JP18: =IF(JP$11="","",IF(AND(JP$11>=$B18,JP$11<=$C18),1,""))
A19: Internal Test | B19: =IF($B$42="","",$B$42) -> 46292 | C19: =IF($B$43="","",$B$43) -> 46295 | D19: Internal Test Start → Complete | E19: =IF($C19="","",IF(TODAY()>$C19,"Done",IF(TODAY()<$B19,"Planned","Current"))) -> Planned | G19: =IF(G$11="","",IF(AND(G$11>=$B19,G$11<=$C19),1,"")) | H19: =IF(H$11="","",IF(AND(H$11>=$B19,H$11<=$C19),1,"")) | I19: =IF(I$11="","",IF(AND(I$11>=$B19,I$11<=$C19),1,"")) | J19: =IF(J$11="","",IF(AND(J$11>=$B19,J$11<=$C19),1,"")) | K19: =IF(K$11="","",IF(AND(K$11>=$B19,K$11<=$C19),1,"")) | L19: =IF(L$11="","",IF(AND(L$11>=$B19,L$11<=$C19),1,"")) | M19: =IF(M$11="","",IF(AND(M$11>=$B19,M$11<=$C19),1,"")) | N19: =IF(N$11="","",IF(AND(N$11>=$B19,N$11<=$C19),1,"")) | ... JP19: =IF(JP$11="","",IF(AND(JP$11>=$B19,JP$11<=$C19),1,""))
A20: FAT | B20: =IF($B$44="","",$B$44) -> 46297 | C20: =IF($B$45="","",$B$45) -> 46304 | D20: FAT Start → Complete | E20: =IF($C20="","",IF(TODAY()>$C20,"Done",IF(TODAY()<$B20,"Planned","Current"))) -> Planned | G20: =IF(G$11="","",IF(AND(G$11>=$B20,G$11<=$C20),1,"")) | H20: =IF(H$11="","",IF(AND(H$11>=$B20,H$11<=$C20),1,"")) | I20: =IF(I$11="","",IF(AND(I$11>=$B20,I$11<=$C20),1,"")) | J20: =IF(J$11="","",IF(AND(J$11>=$B20,J$11<=$C20),1,"")) | K20: =IF(K$11="","",IF(AND(K$11>=$B20,K$11<=$C20),1,"")) | L20: =IF(L$11="","",IF(AND(L$11>=$B20,L$11<=$C20),1,"")) | M20: =IF(M$11="","",IF(AND(M$11>=$B20,M$11<=$C20),1,"")) | N20: =IF(N$11="","",IF(AND(N$11>=$B20,N$11<=$C20),1,"")) | ... JP20: =IF(JP$11="","",IF(AND(JP$11>=$B20,JP$11<=$C20),1,""))
A21: Delivery / ROS | B21: =IF($B$46="","",$B$46) -> 46312 | C21: =IF($B$47="","",$B$47) -> 46315 | D21: Delivery → ROS | E21: =IF($C21="","",IF(TODAY()>$C21,"Done",IF(TODAY()<$B21,"Planned","Current"))) -> Planned | G21: =IF(G$11="","",IF(AND(G$11>=$B21,G$11<=$C21),1,"")) | H21: =IF(H$11="","",IF(AND(H$11>=$B21,H$11<=$C21),1,"")) | I21: =IF(I$11="","",IF(AND(I$11>=$B21,I$11<=$C21),1,"")) | J21: =IF(J$11="","",IF(AND(J$11>=$B21,J$11<=$C21),1,"")) | K21: =IF(K$11="","",IF(AND(K$11>=$B21,K$11<=$C21),1,"")) | L21: =IF(L$11="","",IF(AND(L$11>=$B21,L$11<=$C21),1,"")) | M21: =IF(M$11="","",IF(AND(M$11>=$B21,M$11<=$C21),1,"")) | N21: =IF(N$11="","",IF(AND(N$11>=$B21,N$11<=$C21),1,"")) | ... JP21: =IF(JP$11="","",IF(AND(JP$11>=$B21,JP$11<=$C21),1,""))
A28: Select a Tag No. in A6. The daily phase Gantt updates automatically from the linked sheets.
A32: Contract Signed | B32: =IFERROR(INDEX(Project_Tracker!$E$2:$E$101,MATCH($A$6,Project_Tracker!$AL$2:$AL$101,0)),"") -> 46091
A33: Level 1 Plan | B33: =IFERROR(INDEX(Project_Tracker!$N$2:$N$101,MATCH($A$6,Project_Tracker!$AL$2:$AL$101,0)),"") -> 46119
A34: Input Frozen | B34: =IFERROR(INDEX(Project_Tracker!$O$2:$O$101,MATCH($A$6,Project_Tracker!$AL$2:$AL$101,0)),"") -> 46074
A35: Drawing Approval | B35: =IFERROR(INDEX(Project_Tracker!$P$2:$P$101,MATCH($A$6,Project_Tracker!$AL$2:$AL$101,0)),"") -> 46094
A36: BOM Pass to PR | B36: =IFERROR(INDEX(Project_Tracker!$Q$2:$Q$101,MATCH($A$6,Project_Tracker!$AL$2:$AL$101,0)),"") -> 46101
A37: PR Schedule | B37: =IFERROR(INDEX(Project_Tracker!$R$2:$R$101,MATCH($A$6,Project_Tracker!$AL$2:$AL$101,0)),"") -> 46097
A38: Components PO Plan | B38: =IFERROR(INDEX(Project_Tracker!$S$2:$S$101,MATCH($A$6,Project_Tracker!$AL$2:$AL$101,0)),"") -> 46104
A39: Production Start | B39: =IFERROR(INDEX(Project_Tracker!$T$2:$T$101,MATCH($A$6,Project_Tracker!$AL$2:$AL$101,0)),"") -> 46244
A40: Production Complete | B40: =IFERROR(INDEX(Project_Tracker!$U$2:$U$101,MATCH($A$6,Project_Tracker!$AL$2:$AL$101,0)),"") -> 46289
A41: NOI Date | B41: =IFERROR(INDEX(Project_Tracker!$V$2:$V$101,MATCH($A$6,Project_Tracker!$AL$2:$AL$101,0)),"") -> 46269
A42: Internal Test Start | B42: =IFERROR(INDEX(Project_Tracker!$W$2:$W$101,MATCH($A$6,Project_Tracker!$AL$2:$AL$101,0)),"") -> 46292
A43: Internal Test Complete | B43: =IFERROR(INDEX(Project_Tracker!$X$2:$X$101,MATCH($A$6,Project_Tracker!$AL$2:$AL$101,0)),"") -> 46295
A44: FAT Start | B44: =IFERROR(INDEX(Project_Tracker!$Y$2:$Y$101,MATCH($A$6,Project_Tracker!$AL$2:$AL$101,0)),"") -> 46297
A45: FAT Complete | B45: =IFERROR(INDEX(Project_Tracker!$Z$2:$Z$101,MATCH($A$6,Project_Tracker!$AL$2:$AL$101,0)),"") -> 46304
A46: Delivery | B46: =IFERROR(INDEX(Project_Tracker!$AA$2:$AA$101,MATCH($A$6,Project_Tracker!$AL$2:$AL$101,0)),"") -> 46312
A47: ROS | B47: =IFERROR(INDEX(Project_Tracker!$F$2:$F$101,MATCH($A$6,Project_Tracker!$AL$2:$AL$101,0)),"") -> 46315

Sheet Project_Tracker
A1: TAG NO. | B1: DESCRIPTION | C1: PRODUCT TYPE | D1: CUSTOMER | E1: CONTRACT SIGNED | F1: ROS | G1: CONTRACT NO. | H1: SALES REF | I1: PROJECT MANAGER | J1: ENGINEER OWNER | K1: PROCUREMENT OWNER | L1: PRODUCTION OWNER | M1: FAT OWNER | N1: LEVEL 1 PLAN | O1: INPUT FROZEN | P1: DRAWING APPROVAL | Q1: BOM PASS TO PR | R1: PR SCHEDULE | S1: COMPONENTS PO PLAN | T1: PRODUCTION START | U1: PRODUCTION COMPLETE | V1: NOI DATE | W1: INTERNAL TEST START | X1: INTERNAL TEST COMPLETE | Y1: FAT START | Z1: FAT COMPLETE | AA1: DELIVERY | AB1: LEVEL 1 NO. | AC1: BOM NO. | AD1: PR NO. | AE1: NOI NO. | AF1: DELIVERY ACTUAL / ETA | AG1: ARRIVAL STATUS | AH1: OVERALL STATUS | AI1: DAYS TO ROS | AJ1: NOTES | AK1: TYPE KEY | AL1: RESOLVED TAG | AM1: RESOLVED DESCRIPTION
A2: 123456 | B2: Chiller Water Unit | C2: =IF($AL2="","",IFERROR(INDEX(Product_Registry!$C$2:$C$101,MATCH($AL2,Product_Registry!$A$2:$A$101,0)),"")) -> 冷水机组 | D2: =IF($AL2="","",IFERROR(INDEX(Product_Registry!$D$2:$D$101,MATCH($AL2,Product_Registry!$A$2:$A$101,0)),"")) -> Sample Customer | E2: =IF($AL2="","",IFERROR(INDEX(Product_Registry!$E$2:$E$101,MATCH($AL2,Product_Registry!$A$2:$A$101,0)),"")) -> 46091 | F2: =IF($AL2="","",IFERROR(INDEX(Product_Registry!$F$2:$F$101,MATCH($AL2,Product_Registry!$A$2:$A$101,0)),"")) -> 46315 | G2: =IF($AL2="","",IFERROR(INDEX(Product_Registry!$G$2:$G$101,MATCH($AL2,Product_Registry!$A$2:$A$101,0)),"")) -> CN-2026-001 | H2: =IF($AL2="","",IFERROR(INDEX(Product_Registry!$H$2:$H$101,MATCH($AL2,Product_Registry!$A$2:$A$101,0)),"")) -> P84 Pilot | I2: =IF($AL2="","",IFERROR(INDEX(Product_Registry!$I$2:$I$101,MATCH($AL2,Product_Registry!$A$2:$A$101,0)),"")) -> PM Owner | J2: =IF($AL2="","",IFERROR(INDEX(Product_Registry!$J$2:$J$101,MATCH($AL2,Product_Registry!$A$2:$A$101,0)),"")) -> Engineering Owner | K2: =IF($AL2="","",IFERROR(INDEX(Product_Registry!$K$2:$K$101,MATCH($AL2,Product_Registry!$A$2:$A$101,0)),"")) -> Procurement Owner | L2: =IF($AL2="","",IFERROR(INDEX(Product_Registry!$L$2:$L$101,MATCH($AL2,Product_Registry!$A$2:$A$101,0)),"")) -> Production Owner | M2: =IF($AL2="","",IFERROR(INDEX(Product_Registry!$M$2:$M$101,MATCH($AL2,Product_Registry!$A$2:$A$101,0)),"")) -> QA / FAT Owner | N2: =IF($AL2="","",$E2+SUMIFS('Logic & Lists'!$E$4:$E$200,'Logic & Lists'!$A$4:$A$200,$AK2,'Logic & Lists'!$C$4:$C$200,"Level 1 Schedule")) -> 46119 | O2: =IF($AL2="","",$P2+SUMIFS('Logic & Lists'!$E$4:$E$200,'Logic & Lists'!$A$4:$A$200,$AK2,'Logic & Lists'!$C$4:$C$200,"Input Frozen")) -> 46074 | P2: =IF($AL2="","",$Q2+SUMIFS('Logic & Lists'!$E$4:$E$200,'Logic & Lists'!$A$4:$A$200,$AK2,'Logic & Lists'!$C$4:$C$200,"Drawing Approval")) -> 46094 | Q2: =IF($AL2="","",$S2+SUMIFS('Logic & Lists'!$E$4:$E$200,'Logic & Lists'!$A$4:$A$200,$AK2,'Logic & Lists'!$C$4:$C$200,"BOM Pass to PR")) -> 46101 | R2: =IF($AL2="","",$S2+SUMIFS('Logic & Lists'!$E$4:$E$200,'Logic & Lists'!$A$4:$A$200,$AK2,'Logic & Lists'!$C$4:$C$200,"PR Schedule")) -> 46097 | S2: =IF($AL2="","",$T2+SUMIFS('Logic & Lists'!$E$4:$E$200,'Logic & Lists'!$A$4:$A$200,$AK2,'Logic & Lists'!$C$4:$C$200,"Components PO Plan")) -> 46104 | T2: =IF($AL2="","",$U2+SUMIFS('Logic & Lists'!$E$4:$E$200,'Logic & Lists'!$A$4:$A$200,$AK2,'Logic & Lists'!$C$4:$C$200,"Production Start")) -> 46244 | U2: =IF($AL2="","",$W2+SUMIFS('Logic & Lists'!$E$4:$E$200,'Logic & Lists'!$A$4:$A$200,$AK2,'Logic & Lists'!$C$4:$C$200,"Production Complete")) -> 46289 | V2: =IF($AL2="","",$Y2+SUMIFS('Logic & Lists'!$E$4:$E$200,'Logic & Lists'!$A$4:$A$200,$AK2,'Logic & Lists'!$C$4:$C$200,"NOI Date")) -> 46269 | W2: =IF($AL2="","",$X2+SUMIFS('Logic & Lists'!$E$4:$E$200,'Logic & Lists'!$A$4:$A$200,$AK2,'Logic & Lists'!$C$4:$C$200,"Internal Test Start")) -> 46292 | X2: =IF($AL2="","",$Y2+SUMIFS('Logic & Lists'!$E$4:$E$200,'Logic & Lists'!$A$4:$A$200,$AK2,'Logic & Lists'!$C$4:$C$200,"Internal Test Complete")) -> 46295 | Y2: =IF($AL2="","",$AA2+SUMIFS('Logic & Lists'!$E$4:$E$200,'Logic & Lists'!$A$4:$A$200,$AK2,'Logic & Lists'!$C$4:$C$200,"FAT Start")) -> 46297 | Z2: =IF($AL2="","",$Y2+SUMIFS('Logic & Lists'!$E$4:$E$200,'Logic & Lists'!$A$4:$A$200,$AK2,'Logic & Lists'!$C$4:$C$200,"FAT Complete")) -> 46304 | AA2: =IF($AL2="","",$F2+SUMIFS('Logic & Lists'!$E$4:$E$200,'Logic & Lists'!$A$4:$A$200,$AK2,'Logic & Lists'!$C$4:$C$200,"Delivery")) -> 46312 | AH2: =IF($AL2="","",IF($AI2<0,"At Risk",IF($AI2<=30,"Watch","On Track"))) -> On Track | AI2: =IF($F2="","",$F2-TODAY()) -> 63 | AK2: =IF($AL2="","",IF(COUNTIF('Logic & Lists'!$A$4:$A$200,$C2)>0,$C2,"Default")) -> 冷水机组 | AL2: =IF($A2<>"",$A2,IF($B2<>"",IFERROR(INDEX(Product_Registry!$A$2:$A$101,MATCH($B2,Product_Registry!$B$2:$B$101,0)),IFERROR(INDEX(Product_Registry!$A$2:$A$101,MATCH("*"&$B2&"*",Product_Registry!$B$2:$B$101,0)),"")),"")) -> 123456 | AM2: =IF($AL2="","",IFERROR(INDEX(Product_Registry!$B$2:$B$101,MATCH($AL2,Product_Registry!$A$2:$A$101,0)),"")) -> Chiller Water Unit
C3: =IF($AL3="","",IFERROR(INDEX(Product_Registry!$C$2:$C$101,MATCH($AL3,Product_Registry!$A$2:$A$101,0)),"")) | D3: =IF($AL3="","",IFERROR(INDEX(Product_Registry!$D$2:$D$101,MATCH($AL3,Product_Registry!$A$2:$A$101,0)),"")) | E3: =IF($AL3="","",IFERROR(INDEX(Product_Registry!$E$2:$E$101,MATCH($AL3,Product_Registry!$A$2:$A$101,0)),"")) | F3: =IF($AL3="","",IFERROR(INDEX(Product_Registry!$F$2:$F$101,MATCH($AL3,Product_Registry!$A$2:$A$101,0)),"")) | G3: =IF($AL3="","",IFERROR(INDEX(Product_Registry!$G$2:$G$101,MATCH($AL3,Product_Registry!$A$2:$A$101,0)),"")) | H3: =IF($AL3="","",IFERROR(INDEX(Product_Registry!$H$2:$H$101,MATCH($AL3,Product_Registry!$A$2:$A$101,0)),"")) | I3: =IF($AL3="","",IFERROR(INDEX(Product_Registry!$I$2:$I$101,MATCH($AL3,Product_Registry!$A$2:$A$101,0)),"")) | J3: =IF($AL3="","",IFERROR(INDEX(Product_Registry!$J$2:$J$101,MATCH($AL3,Product_Registry!$A$2:$A$101,0)),"")) | K3: =IF($AL3="","",IFERROR(INDEX(Product_Registry!$K$2:$K$101,MATCH($AL3,Product_Registry!$A$2:$A$101,0)),"")) | L3: =IF($AL3="","",IFERROR(INDEX(Product_Registry!$L$2:$L$101,MATCH($AL3,Product_Registry!$A$2:$A$101,0)),"")) | M3: =IF($AL3="","",IFERROR(INDEX(Product_Registry!$M$2:$M$101,MATCH($AL3,Product_Registry!$A$2:$A$101,0)),"")) | N3: =IF($AL3="","",$E3+SUMIFS('Logic & Lists'!$E$4:$E$200,'Logic & Lists'!$A$4:$A$200,$AK3,'Logic & Lists'!$C$4:$C$200,"Level 1 Schedule")) | O3: =IF($AL3="","",$P3+SUMIFS('Logic & Lists'!$E$4:$E$200,'Logic & Lists'!$A$4:$A$200,$AK3,'Logic & Lists'!$C$4:$C$200,"Input Frozen")) | P3: =IF($AL3="","",$Q3+SUMIFS('Logic & Lists'!$E$4:$E$200,'Logic & Lists'!$A$4:$A$200,$AK3,'Logic & Lists'!$C$4:$C$200,"Drawing Approval")) | Q3: =IF($AL3="","",$S3+SUMIFS('Logic & Lists'!$E$4:$E$200,'Logic & Lists'!$A$4:$A$200,$AK3,'Logic & Lists'!$C$4:$C$200,"BOM Pass to PR")) | R3: =IF($AL3="","",$S3+SUMIFS('Logic & Lists'!$E$4:$E$200,'Logic & Lists'!$A$4:$A$200,$AK3,'Logic & Lists'!$C$4:$C$200,"PR Schedule")) | S3: =IF($AL3="","",$T3+SUMIFS('Logic & Lists'!$E$4:$E$200,'Logic & Lists'!$A$4:$A$200,$AK3,'Logic & Lists'!$C$4:$C$200,"Components PO Plan")) | T3: =IF($AL3="","",$U3+SUMIFS('Logic & Lists'!$E$4:$E$200,'Logic & Lists'!$A$4:$A$200,$AK3,'Logic & Lists'!$C$4:$C$200,"Production Start")) | U3: =IF($AL3="","",$W3+SUMIFS('Logic & Lists'!$E$4:$E$200,'Logic & Lists'!$A$4:$A$200,$AK3,'Logic & Lists'!$C$4:$C$200,"Production Complete")) | V3: =IF($AL3="","",$Y3+SUMIFS('Logic & Lists'!$E$4:$E$200,'Logic & Lists'!$A$4:$A$200,$AK3,'Logic & Lists'!$C$4:$C$200,"NOI Date")) | W3: =IF($AL3="","",$X3+SUMIFS('Logic & Lists'!$E$4:$E$200,'Logic & Lists'!$A$4:$A$200,$AK3,'Logic & Lists'!$C$4:$C$200,"Internal Test Start")) | X3: =IF($AL3="","",$Y3+SUMIFS('Logic & Lists'!$E$4:$E$200,'Logic & Lists'!$A$4:$A$200,$AK3,'Logic & Lists'!$C$4:$C$200,"Internal Test Complete")) | Y3: =IF($AL3="","",$AA3+SUMIFS('Logic & Lists'!$E$4:$E$200,'Logic & Lists'!$A$4:$A$200,$AK3,'Logic & Lists'!$C$4:$C$200,"FAT Start")) | Z3: =IF($AL3="","",$Y3+SUMIFS('Logic & Lists'!$E$4:$E$200,'Logic & Lists'!$A$4:$A$200,$AK3,'Logic & Lists'!$C$4:$C$200,"FAT Complete")) | AA3: =IF($AL3="","",$F3+SUMIFS('Logic & Lists'!$E$4:$E$200,'Logic & Lists'!$A$4:$A$200,$AK3,'Logic & Lists'!$C$4:$C$200,"Delivery")) | AH3: =IF($AL3="","",IF($AI3<0,"At Risk",IF($AI3<=30,"Watch","On Track"))) | AI3: =IF($F3="","",$F3-TODAY()) | AK3: =IF($AL3="","",IF(COUNTIF('Logic & Lists'!$A$4:$A$200,$C3)>0,$C3,"Default")) | AL3: =IF($A3<>"",$A3,IF($B3<>"",IFERROR(INDEX(Product_Registry!$A$2:$A$101,MATCH($B3,Product_Registry!$B$2:$B$101,0)),IFERROR(INDEX(Product_Registry!$A$2:$A$101,MATCH("*"&$B3&"*",Product_Registry!$B$2:$B$101,0)),"")),"")) | AM3: =IF($AL3="","",IFERROR(INDEX(Product_Registry!$B$2:$B$101,MATCH($AL3,Product_Registry!$A$2:$A$101,0)),""))
C4: =IF($AL4="","",IFERROR(INDEX(Product_Registry!$C$2:$C$101,MATCH($AL4,Product_Registry!$A$2:$A$101,0)),"")) | D4: =IF($AL4="","",IFERROR(INDEX(Product_Registry!$D$2:$D$101,MATCH($AL4,Product_Registry!$A$2:$A$101,0)),"")) | E4: =IF($AL4="","",IFERROR(INDEX(Product_Registry!$E$2:$E$101,MATCH($AL4,Product_Registry!$A$2:$A$101,0)),"")) | F4: =IF($AL4="","",IFERROR(INDEX(Product_Registry!$F$2:$F$101,MATCH($AL4,Product_Registry!$A$2:$A$101,0)),"")) | G4: =IF($AL4="","",IFERROR(INDEX(Product_Registry!$G$2:$G$101,MATCH($AL4,Product_Registry!$A$2:$A$101,0)),"")) | H4: =IF($AL4="","",IFERROR(INDEX(Product_Registry!$H$2:$H$101,MATCH($AL4,Product_Registry!$A$2:$A$101,0)),"")) | I4: =IF($AL4="","",IFERROR(INDEX(Product_Registry!$I$2:$I$101,MATCH($AL4,Product_Registry!$A$2:$A$101,0)),"")) | J4: =IF($AL4="","",IFERROR(INDEX(Product_Registry!$J$2:$J$101,MATCH($AL4,Product_Registry!$A$2:$A$101,0)),"")) | K4: =IF($AL4="","",IFERROR(INDEX(Product_Registry!$K$2:$K$101,MATCH($AL4,Product_Registry!$A$2:$A$101,0)),"")) | L4: =IF($AL4="","",IFERROR(INDEX(Product_Registry!$L$2:$L$101,MATCH($AL4,Product_Registry!$A$2:$A$101,0)),"")) | M4: =IF($AL4="","",IFERROR(INDEX(Product_Registry!$M$2:$M$101,MATCH($AL4,Product_Registry!$A$2:$A$101,0)),"")) | N4: =IF($AL4="","",$E4+SUMIFS('Logic & Lists'!$E$4:$E$200,'Logic & Lists'!$A$4:$A$200,$AK4,'Logic & Lists'!$C$4:$C$200,"Level 1 Schedule")) | O4: =IF($AL4="","",$P4+SUMIFS('Logic & Lists'!$E$4:$E$200,'Logic & Lists'!$A$4:$A$200,$AK4,'Logic & Lists'!$C$4:$C$200,"Input Frozen")) | P4: =IF($AL4="","",$Q4+SUMIFS('Logic & Lists'!$E$4:$E$200,'Logic & Lists'!$A$4:$A$200,$AK4,'Logic & Lists'!$C$4:$C$200,"Drawing Approval")) | Q4: =IF($AL4="","",$S4+SUMIFS('Logic & Lists'!$E$4:$E$200,'Logic & Lists'!$A$4:$A$200,$AK4,'Logic & Lists'!$C$4:$C$200,"BOM Pass to PR")) | R4: =IF($AL4="","",$S4+SUMIFS('Logic & Lists'!$E$4:$E$200,'Logic & Lists'!$A$4:$A$200,$AK4,'Logic & Lists'!$C$4:$C$200,"PR Schedule")) | S4: =IF($AL4="","",$T4+SUMIFS('Logic & Lists'!$E$4:$E$200,'Logic & Lists'!$A$4:$A$200,$AK4,'Logic & Lists'!$C$4:$C$200,"Components PO Plan")) | T4: =IF($AL4="","",$U4+SUMIFS('Logic & Lists'!$E$4:$E$200,'Logic & Lists'!$A$4:$A$200,$AK4,'Logic & Lists'!$C$4:$C$200,"Production Start")) | U4: =IF($AL4="","",$W4+SUMIFS('Logic & Lists'!$E$4:$E$200,'Logic & Lists'!$A$4:$A$200,$AK4,'Logic & Lists'!$C$4:$C$200,"Production Complete")) | V4: =IF($AL4="","",$Y4+SUMIFS('Logic & Lists'!$E$4:$E$200,'Logic & Lists'!$A$4:$A$200,$AK4,'Logic & Lists'!$C$4:$C$200,"NOI Date")) | W4: =IF($AL4="","",$X4+SUMIFS('Logic & Lists'!$E$4:$E$200,'Logic & Lists'!$A$4:$A$200,$AK4,'Logic & Lists'!$C$4:$C$200,"Internal Test Start")) | X4: =IF($AL4="","",$Y4+SUMIFS('Logic & Lists'!$E$4:$E$200,'Logic & Lists'!$A$4:$A$200,$AK4,'Logic & Lists'!$C$4:$C$200,"Internal Test Complete")) | Y4: =IF($AL4="","",$AA4+SUMIFS('Logic & Lists'!$E$4:$E$200,'Logic & Lists'!$A$4:$A$200,$AK4,'Logic & Lists'!$C$4:$C$200,"FAT Start")) | Z4: =IF($AL4="","",$Y4+SUMIFS('Logic & Lists'!$E$4:$E$200,'Logic & Lists'!$A$4:$A$200,$AK4,'Logic & Lists'!$C$4:$C$200,"FAT Complete")) | AA4: =IF($AL4="","",$F4+SUMIFS('Logic & Lists'!$E$4:$E$200,'Logic & Lists'!$A$4:$A$200,$AK4,'Logic & Lists'!$C$4:$C$200,"Delivery")) | AH4: =IF($AL4="","",IF($AI4<0,"At Risk",IF($AI4<=30,"Watch","On Track"))) | AI4: =IF($F4="","",$F4-TODAY()) | AK4: =IF($AL4="","",IF(COUNTIF('Logic & Lists'!$A$4:$A$200,$C4)>0,$C4,"Default")) | AL4: =IF($A4<>"",$A4,IF($B4<>"",IFERROR(INDEX(Product_Registry!$A$2:$A$101,MATCH($B4,Product_Registry!$B$2:$B$101,0)),IFERROR(INDEX(Product_Registry!$A$2:$A$101,MATCH("*"&$B4&"*",Product_Registry!$B$2:$B$101,0)),"")),"")) | AM4: =IF($AL4="","",IFERROR(INDEX(Product_Registry!$B$2:$B$101,MATCH($AL4,Product_Registry!$A$2:$A$101,0)),""))
C5: =IF($AL5="","",IFERROR(INDEX(Product_Registry!$C$2:$C$101,MATCH($AL5,Product_Registry!$A$2:$A$101,0)),"")) | D5: =IF($AL5="","",IFERROR(INDEX(Product_Registry!$D$2:$D$101,MATCH($AL5,Product_Registry!$A$2:$A$101,0)),"")) | E5: =IF($AL5="","",IFERROR(INDEX(Product_Registry!$E$2:$E$101,MATCH($AL5,Product_Registry!$A$2:$A$101,0)),"")) | F5: =IF($AL5="","",IFERROR(INDEX(Product_Registry!$F$2:$F$101,MATCH($AL5,Product_Registry!$A$2:$A$101,0)),"")) | G5: =IF($AL5="","",IFERROR(INDEX(Product_Registry!$G$2:$G$101,MATCH($AL5,Product_Registry!$A$2:$A$101,0)),"")) | H5: =IF($AL5="","",IFERROR(INDEX(Product_Registry!$H$2:$H$101,MATCH($AL5,Product_Registry!$A$2:$A$101,0)),"")) | I5: =IF($AL5="","",IFERROR(INDEX(Product_Registry!$I$2:$I$101,MATCH($AL5,Product_Registry!$A$2:$A$101,0)),"")) | J5: =IF($AL5="","",IFERROR(INDEX(Product_Registry!$J$2:$J$101,MATCH($AL5,Product_Registry!$A$2:$A$101,0)),"")) | K5: =IF($AL5="","",IFERROR(INDEX(Product_Registry!$K$2:$K$101,MATCH($AL5,Product_Registry!$A$2:$A$101,0)),"")) | L5: =IF($AL5="","",IFERROR(INDEX(Product_Registry!$L$2:$L$101,MATCH($AL5,Product_Registry!$A$2:$A$101,0)),"")) | M5: =IF($AL5="","",IFERROR(INDEX(Product_Registry!$M$2:$M$101,MATCH($AL5,Product_Registry!$A$2:$A$101,0)),"")) | N5: =IF($AL5="","",$E5+SUMIFS('Logic & Lists'!$E$4:$E$200,'Logic & Lists'!$A$4:$A$200,$AK5,'Logic & Lists'!$C$4:$C$200,"Level 1 Schedule")) | O5: =IF($AL5="","",$P5+SUMIFS('Logic & Lists'!$E$4:$E$200,'Logic & Lists'!$A$4:$A$200,$AK5,'Logic & Lists'!$C$4:$C$200,"Input Frozen")) | P5: =IF($AL5="","",$Q5+SUMIFS('Logic & Lists'!$E$4:$E$200,'Logic & Lists'!$A$4:$A$200,$AK5,'Logic & Lists'!$C$4:$C$200,"Drawing Approval")) | Q5: =IF($AL5="","",$S5+SUMIFS('Logic & Lists'!$E$4:$E$200,'Logic & Lists'!$A$4:$A$200,$AK5,'Logic & Lists'!$C$4:$C$200,"BOM Pass to PR")) | R5: =IF($AL5="","",$S5+SUMIFS('Logic & Lists'!$E$4:$E$200,'Logic & Lists'!$A$4:$A$200,$AK5,'Logic & Lists'!$C$4:$C$200,"PR Schedule")) | S5: =IF($AL5="","",$T5+SUMIFS('Logic & Lists'!$E$4:$E$200,'Logic & Lists'!$A$4:$A$200,$AK5,'Logic & Lists'!$C$4:$C$200,"Components PO Plan")) | T5: =IF($AL5="","",$U5+SUMIFS('Logic & Lists'!$E$4:$E$200,'Logic & Lists'!$A$4:$A$200,$AK5,'Logic & Lists'!$C$4:$C$200,"Production Start")) | U5: =IF($AL5="","",$W5+SUMIFS('Logic & Lists'!$E$4:$E$200,'Logic & Lists'!$A$4:$A$200,$AK5,'Logic & Lists'!$C$4:$C$200,"Production Complete")) | V5: =IF($AL5="","",$Y5+SUMIFS('Logic & Lists'!$E$4:$E$200,'Logic & Lists'!$A$4:$A$200,$AK5,'Logic & Lists'!$C$4:$C$200,"NOI Date")) | W5: =IF($AL5="","",$X5+SUMIFS('Logic & Lists'!$E$4:$E$200,'Logic & Lists'!$A$4:$A$200,$AK5,'Logic & Lists'!$C$4:$C$200,"Internal Test Start")) | X5: =IF($AL5="","",$Y5+SUMIFS('Logic & Lists'!$E$4:$E$200,'Logic & Lists'!$A$4:$A$200,$AK5,'Logic & Lists'!$C$4:$C$200,"Internal Test Complete")) | Y5: =IF($AL5="","",$AA5+SUMIFS('Logic & Lists'!$E$4:$E$200,'Logic & Lists'!$A$4:$A$200,$AK5,'Logic & Lists'!$C$4:$C$200,"FAT Start")) | Z5: =IF($AL5="","",$Y5+SUMIFS('Logic & Lists'!$E$4:$E$200,'Logic & Lists'!$A$4:$A$200,$AK5,'Logic & Lists'!$C$4:$C$200,"FAT Complete")) | AA5: =IF($AL5="","",$F5+SUMIFS('Logic & Lists'!$E$4:$E$200,'Logic & Lists'!$A$4:$A$200,$AK5,'Logic & Lists'!$C$4:$C$200,"Delivery")) | AH5: =IF($AL5="","",IF($AI5<0,"At Risk",IF($AI5<=30,"Watch","On Track"))) | AI5: =IF($F5="","",$F5-TODAY()) | AK5: =IF($AL5="","",IF(COUNTIF('Logic & Lists'!$A$4:$A$200,$C5)>0,$C5,"Default")) | AL5: =IF($A5<>"",$A5,IF($B5<>"",IFERROR(INDEX(Product_Registry!$A$2:$A$101,MATCH($B5,Product_Registry!$B$2:$B$101,0)),IFERROR(INDEX(Product_Registry!$A$2:$A$101,MATCH("*"&$B5&"*",Product_Registry!$B$2:$B$101,0)),"")),"")) | AM5: =IF($AL5="","",IFERROR(INDEX(Product_Registry!$B$2:$B$101,MATCH($AL5,Product_Registry!$A$2:$A$101,0)),""))
C6: =IF($AL6="","",IFERROR(INDEX(Product_Registry!$C$2:$C$101,MATCH($AL6,Product_Registry!$A$2:$A$101,0)),"")) | D6: =IF($AL6="","",IFERROR(INDEX(Product_Registry!$D$2:$D$101,MATCH($AL6,Product_Registry!$A$2:$A$101,0)),"")) | E6: =IF($AL6="","",IFERROR(INDEX(Product_Registry!$E$2:$E$101,MATCH($AL6,Product_Registry!$A$2:$A$101,0)),"")) | F6: =IF($AL6="","",IFERROR(INDEX(Product_Registry!$F$2:$F$101,MATCH($AL6,Product_Registry!$A$2:$A$101,0)),"")) | G6: =IF($AL6="","",IFERROR(INDEX(Product_Registry!$G$2:$G$101,MATCH($AL6,Product_Registry!$A$2:$A$101,0)),"")) | H6: =IF($AL6="","",IFERROR(INDEX(Product_Registry!$H$2:$H$101,MATCH($AL6,Product_Registry!$A$2:$A$101,0)),"")) | I6: =IF($AL6="","",IFERROR(INDEX(Product_Registry!$I$2:$I$101,MATCH($AL6,Product_Registry!$A$2:$A$101,0)),"")) | J6: =IF($AL6="","",IFERROR(INDEX(Product_Registry!$J$2:$J$101,MATCH($AL6,Product_Registry!$A$2:$A$101,0)),"")) | K6: =IF($AL6="","",IFERROR(INDEX(Product_Registry!$K$2:$K$101,MATCH($AL6,Product_Registry!$A$2:$A$101,0)),"")) | L6: =IF($AL6="","",IFERROR(INDEX(Product_Registry!$L$2:$L$101,MATCH($AL6,Product_Registry!$A$2:$A$101,0)),"")) | M6: =IF($AL6="","",IFERROR(INDEX(Product_Registry!$M$2:$M$101,MATCH($AL6,Product_Registry!$A$2:$A$101,0)),"")) | N6: =IF($AL6="","",$E6+SUMIFS('Logic & Lists'!$E$4:$E$200,'Logic & Lists'!$A$4:$A$200,$AK6,'Logic & Lists'!$C$4:$C$200,"Level 1 Schedule")) | O6: =IF($AL6="","",$P6+SUMIFS('Logic & Lists'!$E$4:$E$200,'Logic & Lists'!$A$4:$A$200,$AK6,'Logic & Lists'!$C$4:$C$200,"Input Frozen")) | P6: =IF($AL6="","",$Q6+SUMIFS('Logic & Lists'!$E$4:$E$200,'Logic & Lists'!$A$4:$A$200,$AK6,'Logic & Lists'!$C$4:$C$200,"Drawing Approval")) | Q6: =IF($AL6="","",$S6+SUMIFS('Logic & Lists'!$E$4:$E$200,'Logic & Lists'!$A$4:$A$200,$AK6,'Logic & Lists'!$C$4:$C$200,"BOM Pass to PR")) | R6: =IF($AL6="","",$S6+SUMIFS('Logic & Lists'!$E$4:$E$200,'Logic & Lists'!$A$4:$A$200,$AK6,'Logic & Lists'!$C$4:$C$200,"PR Schedule")) | S6: =IF($AL6="","",$T6+SUMIFS('Logic & Lists'!$E$4:$E$200,'Logic & Lists'!$A$4:$A$200,$AK6,'Logic & Lists'!$C$4:$C$200,"Components PO Plan")) | T6: =IF($AL6="","",$U6+SUMIFS('Logic & Lists'!$E$4:$E$200,'Logic & Lists'!$A$4:$A$200,$AK6,'Logic & Lists'!$C$4:$C$200,"Production Start")) | U6: =IF($AL6="","",$W6+SUMIFS('Logic & Lists'!$E$4:$E$200,'Logic & Lists'!$A$4:$A$200,$AK6,'Logic & Lists'!$C$4:$C$200,"Production Complete")) | V6: =IF($AL6="","",$Y6+SUMIFS('Logic & Lists'!$E$4:$E$200,'Logic & Lists'!$A$4:$A$200,$AK6,'Logic & Lists'!$C$4:$C$200,"NOI Date")) | W6: =IF($AL6="","",$X6+SUMIFS('Logic & Lists'!$E$4:$E$200,'Logic & Lists'!$A$4:$A$200,$AK6,'Logic & Lists'!$C$4:$C$200,"Internal Test Start")) | X6: =IF($AL6="","",$Y6+SUMIFS('Logic & Lists'!$E$4:$E$200,'Logic & Lists'!$A$4:$A$200,$AK6,'Logic & Lists'!$C$4:$C$200,"Internal Test Complete")) | Y6: =IF($AL6="","",$AA6+SUMIFS('Logic & Lists'!$E$4:$E$200,'Logic & Lists'!$A$4:$A$200,$AK6,'Logic & Lists'!$C$4:$C$200,"FAT Start")) | Z6: =IF($AL6="","",$Y6+SUMIFS('Logic & Lists'!$E$4:$E$200,'Logic & Lists'!$A$4:$A$200,$AK6,'Logic & Lists'!$C$4:$C$200,"FAT Complete")) | AA6: =IF($AL6="","",$F6+SUMIFS('Logic & Lists'!$E$4:$E$200,'Logic & Lists'!$A$4:$A$200,$AK6,'Logic & Lists'!$C$4:$C$200,"Delivery")) | AH6: =IF($AL6="","",IF($AI6<0,"At Risk",IF($AI6<=30,"Watch","On Track"))) | AI6: =IF($F6="","",$F6-TODAY()) | AK6: =IF($AL6="","",IF(COUNTIF('Logic & Lists'!$A$4:$A$200,$C6)>0,$C6,"Default")) | AL6: =IF($A6<>"",$A6,IF($B6<>"",IFERROR(INDEX(Product_Registry!$A$2:$A$101,MATCH($B6,Product_Registry!$B$2:$B$101,0)),IFERROR(INDEX(Product_Registry!$A$2:$A$101,MATCH("*"&$B6&"*",Product_Registry!$B$2:$B$101,0)),"")),"")) | AM6: =IF($AL6="","",IFERROR(INDEX(Product_Registry!$B$2:$B$101,MATCH($AL6,Product_Registry!$A$2:$A$101,0)),""))
C7: =IF($AL7="","",IFERROR(INDEX(Product_Registry!$C$2:$C$101,MATCH($AL7,Product_Registry!$A$2:$A$101,0)),"")) | D7: =IF($AL7="","",IFERROR(INDEX(Product_Registry!$D$2:$D$101,MATCH($AL7,Product_Registry!$A$2:$A$101,0)),"")) | E7: =IF($AL7="","",IFERROR(INDEX(Product_Registry!$E$2:$E$101,MATCH($AL7,Product_Registry!$A$2:$A$101,0)),"")) | F7: =IF($AL7="","",IFERROR(INDEX(Product_Registry!$F$2:$F$101,MATCH($AL7,Product_Registry!$A$2:$A$101,0)),"")) | G7: =IF($AL7="","",IFERROR(INDEX(Product_Registry!$G$2:$G$101,MATCH($AL7,Product_Registry!$A$2:$A$101,0)),"")) | H7: =IF($AL7="","",IFERROR(INDEX(Product_Registry!$H$2:$H$101,MATCH($AL7,Product_Registry!$A$2:$A$101,0)),"")) | I7: =IF($AL7="","",IFERROR(INDEX(Product_Registry!$I$2:$I$101,MATCH($AL7,Product_Registry!$A$2:$A$101,0)),"")) | J7: =IF($AL7="","",IFERROR(INDEX(Product_Registry!$J$2:$J$101,MATCH($AL7,Product_Registry!$A$2:$A$101,0)),"")) | K7: =IF($AL7="","",IFERROR(INDEX(Product_Registry!$K$2:$K$101,MATCH($AL7,Product_Registry!$A$2:$A$101,0)),"")) | L7: =IF($AL7="","",IFERROR(INDEX(Product_Registry!$L$2:$L$101,MATCH($AL7,Product_Registry!$A$2:$A$101,0)),"")) | M7: =IF($AL7="","",IFERROR(INDEX(Product_Registry!$M$2:$M$101,MATCH($AL7,Product_Registry!$A$2:$A$101,0)),"")) | N7: =IF($AL7="","",$E7+SUMIFS('Logic & Lists'!$E$4:$E$200,'Logic & Lists'!$A$4:$A$200,$AK7,'Logic & Lists'!$C$4:$C$200,"Level 1 Schedule")) | O7: =IF($AL7="","",$P7+SUMIFS('Logic & Lists'!$E$4:$E$200,'Logic & Lists'!$A$4:$A$200,$AK7,'Logic & Lists'!$C$4:$C$200,"Input Frozen")) | P7: =IF($AL7="","",$Q7+SUMIFS('Logic & Lists'!$E$4:$E$200,'Logic & Lists'!$A$4:$A$200,$AK7,'Logic & Lists'!$C$4:$C$200,"Drawing Approval")) | Q7: =IF($AL7="","",$S7+SUMIFS('Logic & Lists'!$E$4:$E$200,'Logic & Lists'!$A$4:$A$200,$AK7,'Logic & Lists'!$C$4:$C$200,"BOM Pass to PR")) | R7: =IF($AL7="","",$S7+SUMIFS('Logic & Lists'!$E$4:$E$200,'Logic & Lists'!$A$4:$A$200,$AK7,'Logic & Lists'!$C$4:$C$200,"PR Schedule")) | S7: =IF($AL7="","",$T7+SUMIFS('Logic & Lists'!$E$4:$E$200,'Logic & Lists'!$A$4:$A$200,$AK7,'Logic & Lists'!$C$4:$C$200,"Components PO Plan")) | T7: =IF($AL7="","",$U7+SUMIFS('Logic & Lists'!$E$4:$E$200,'Logic & Lists'!$A$4:$A$200,$AK7,'Logic & Lists'!$C$4:$C$200,"Production Start")) | U7: =IF($AL7="","",$W7+SUMIFS('Logic & Lists'!$E$4:$E$200,'Logic & Lists'!$A$4:$A$200,$AK7,'Logic & Lists'!$C$4:$C$200,"Production Complete")) | V7: =IF($AL7="","",$Y7+SUMIFS('Logic & Lists'!$E$4:$E$200,'Logic & Lists'!$A$4:$A$200,$AK7,'Logic & Lists'!$C$4:$C$200,"NOI Date")) | W7: =IF($AL7="","",$X7+SUMIFS('Logic & Lists'!$E$4:$E$200,'Logic & Lists'!$A$4:$A$200,$AK7,'Logic & Lists'!$C$4:$C$200,"Internal Test Start")) | X7: =IF($AL7="","",$Y7+SUMIFS('Logic & Lists'!$E$4:$E$200,'Logic & Lists'!$A$4:$A$200,$AK7,'Logic & Lists'!$C$4:$C$200,"Internal Test Complete")) | Y7: =IF($AL7="","",$AA7+SUMIFS('Logic & Lists'!$E$4:$E$200,'Logic & Lists'!$A$4:$A$200,$AK7,'Logic & Lists'!$C$4:$C$200,"FAT Start")) | Z7: =IF($AL7="","",$Y7+SUMIFS('Logic & Lists'!$E$4:$E$200,'Logic & Lists'!$A$4:$A$200,$AK7,'Logic & Lists'!$C$4:$C$200,"FAT Complete")) | AA7: =IF($AL7="","",$F7+SUMIFS('Logic & Lists'!$E$4:$E$200,'Logic & Lists'!$A$4:$A$200,$AK7,'Logic & Lists'!$C$4:$C$200,"Delivery")) | AH7: =IF($AL7="","",IF($AI7<0,"At Risk",IF($AI7<=30,"Watch","On Track"))) | AI7: =IF($F7="","",$F7-TODAY()) | AK7: =IF($AL7="","",IF(COUNTIF('Logic & Lists'!$A$4:$A$200,$C7)>0,$C7,"Default")) | AL7: =IF($A7<>"",$A7,IF($B7<>"",IFERROR(INDEX(Product_Registry!$A$2:$A$101,MATCH($B7,Product_Registry!$B$2:$B$101,0)),IFERROR(INDEX(Product_Registry!$A$2:$A$101,MATCH("*"&$B7&"*",Product_Registry!$B$2:$B$101,0)),"")),"")) | AM7: =IF($AL7="","",IFERROR(INDEX(Product_Registry!$B$2:$B$101,MATCH($AL7,Product_Registry!$A$2:$A$101,0)),""))
C8: =IF($AL8="","",IFERROR(INDEX(Product_Registry!$C$2:$C$101,MATCH($AL8,Product_Registry!$A$2:$A$101,0)),"")) | D8: =IF($AL8="","",IFERROR(INDEX(Product_Registry!$D$2:$D$101,MATCH($AL8,Product_Registry!$A$2:$A$101,0)),"")) | E8: =IF($AL8="","",IFERROR(INDEX(Product_Registry!$E$2:$E$101,MATCH($AL8,Product_Registry!$A$2:$A$101,0)),"")) | F8: =IF($AL8="","",IFERROR(INDEX(Product_Registry!$F$2:$F$101,MATCH($AL8,Product_Registry!$A$2:$A$101,0)),"")) | G8: =IF($AL8="","",IFERROR(INDEX(Product_Registry!$G$2:$G$101,MATCH($AL8,Product_Registry!$A$2:$A$101,0)),"")) | H8: =IF($AL8="","",IFERROR(INDEX(Product_Registry!$H$2:$H$101,MATCH($AL8,Product_Registry!$A$2:$A$101,0)),"")) | I8: =IF($AL8="","",IFERROR(INDEX(Product_Registry!$I$2:$I$101,MATCH($AL8,Product_Registry!$A$2:$A$101,0)),"")) | J8: =IF($AL8="","",IFERROR(INDEX(Product_Registry!$J$2:$J$101,MATCH($AL8,Product_Registry!$A$2:$A$101,0)),"")) | K8: =IF($AL8="","",IFERROR(INDEX(Product_Registry!$K$2:$K$101,MATCH($AL8,Product_Registry!$A$2:$A$101,0)),"")) | L8: =IF($AL8="","",IFERROR(INDEX(Product_Registry!$L$2:$L$101,MATCH($AL8,Product_Registry!$A$2:$A$101,0)),"")) | M8: =IF($AL8="","",IFERROR(INDEX(Product_Registry!$M$2:$M$101,MATCH($AL8,Product_Registry!$A$2:$A$101,0)),"")) | N8: =IF($AL8="","",$E8+SUMIFS('Logic & Lists'!$E$4:$E$200,'Logic & Lists'!$A$4:$A$200,$AK8,'Logic & Lists'!$C$4:$C$200,"Level 1 Schedule")) | O8: =IF($AL8="","",$P8+SUMIFS('Logic & Lists'!$E$4:$E$200,'Logic & Lists'!$A$4:$A$200,$AK8,'Logic & Lists'!$C$4:$C$200,"Input Frozen")) | P8: =IF($AL8="","",$Q8+SUMIFS('Logic & Lists'!$E$4:$E$200,'Logic & Lists'!$A$4:$A$200,$AK8,'Logic & Lists'!$C$4:$C$200,"Drawing Approval")) | Q8: =IF($AL8="","",$S8+SUMIFS('Logic & Lists'!$E$4:$E$200,'Logic & Lists'!$A$4:$A$200,$AK8,'Logic & Lists'!$C$4:$C$200,"BOM Pass to PR")) | R8: =IF($AL8="","",$S8+SUMIFS('Logic & Lists'!$E$4:$E$200,'Logic & Lists'!$A$4:$A$200,$AK8,'Logic & Lists'!$C$4:$C$200,"PR Schedule")) | S8: =IF($AL8="","",$T8+SUMIFS('Logic & Lists'!$E$4:$E$200,'Logic & Lists'!$A$4:$A$200,$AK8,'Logic & Lists'!$C$4:$C$200,"Components PO Plan")) | T8: =IF($AL8="","",$U8+SUMIFS('Logic & Lists'!$E$4:$E$200,'Logic & Lists'!$A$4:$A$200,$AK8,'Logic & Lists'!$C$4:$C$200,"Production Start")) | U8: =IF($AL8="","",$W8+SUMIFS('Logic & Lists'!$E$4:$E$200,'Logic & Lists'!$A$4:$A$200,$AK8,'Logic & Lists'!$C$4:$C$200,"Production Complete")) | V8: =IF($AL8="","",$Y8+SUMIFS('Logic & Lists'!$E$4:$E$200,'Logic & Lists'!$A$4:$A$200,$AK8,'Logic & Lists'!$C$4:$C$200,"NOI Date")) | W8: =IF($AL8="","",$X8+SUMIFS('Logic & Lists'!$E$4:$E$200,'Logic & Lists'!$A$4:$A$200,$AK8,'Logic & Lists'!$C$4:$C$200,"Internal Test Start")) | X8: =IF($AL8="","",$Y8+SUMIFS('Logic & Lists'!$E$4:$E$200,'Logic & Lists'!$A$4:$A$200,$AK8,'Logic & Lists'!$C$4:$C$200,"Internal Test Complete")) | Y8: =IF($AL8="","",$AA8+SUMIFS('Logic & Lists'!$E$4:$E$200,'Logic & Lists'!$A$4:$A$200,$AK8,'Logic & Lists'!$C$4:$C$200,"FAT Start")) | Z8: =IF($AL8="","",$Y8+SUMIFS('Logic & Lists'!$E$4:$E$200,'Logic & Lists'!$A$4:$A$200,$AK8,'Logic & Lists'!$C$4:$C$200,"FAT Complete")) | AA8: =IF($AL8="","",$F8+SUMIFS('Logic & Lists'!$E$4:$E$200,'Logic & Lists'!$A$4:$A$200,$AK8,'Logic & Lists'!$C$4:$C$200,"Delivery")) | AH8: =IF($AL8="","",IF($AI8<0,"At Risk",IF($AI8<=30,"Watch","On Track"))) | AI8: =IF($F8="","",$F8-TODAY()) | AK8: =IF($AL8="","",IF(COUNTIF('Logic & Lists'!$A$4:$A$200,$C8)>0,$C8,"Default")) | AL8: =IF($A8<>"",$A8,IF($B8<>"",IFERROR(INDEX(Product_Registry!$A$2:$A$101,MATCH($B8,Product_Registry!$B$2:$B$101,0)),IFERROR(INDEX(Product_Registry!$A$2:$A$101,MATCH("*"&$B8&"*",Product_Registry!$B$2:$B$101,0)),"")),"")) | AM8: =IF($AL8="","",IFERROR(INDEX(Product_Registry!$B$2:$B$101,MATCH($AL8,Product_Registry!$A$2:$A$101,0)),""))
C9: =IF($AL9="","",IFERROR(INDEX(Product_Registry!$C$2:$C$101,MATCH($AL9,Product_Registry!$A$2:$A$101,0)),"")) | D9: =IF($AL9="","",IFERROR(INDEX(Product_Registry!$D$2:$D$101,MATCH($AL9,Product_Registry!$A$2:$A$101,0)),"")) | E9: =IF($AL9="","",IFERROR(INDEX(Product_Registry!$E$2:$E$101,MATCH($AL9,Product_Registry!$A$2:$A$101,0)),"")) | F9: =IF($AL9="","",IFERROR(INDEX(Product_Registry!$F$2:$F$101,MATCH($AL9,Product_Registry!$A$2:$A$101,0)),"")) | G9: =IF($AL9="","",IFERROR(INDEX(Product_Registry!$G$2:$G$101,MATCH($AL9,Product_Registry!$A$2:$A$101,0)),"")) | H9: =IF($AL9="","",IFERROR(INDEX(Product_Registry!$H$2:$H$101,MATCH($AL9,Product_Registry!$A$2:$A$101,0)),"")) | I9: =IF($AL9="","",IFERROR(INDEX(Product_Registry!$I$2:$I$101,MATCH($AL9,Product_Registry!$A$2:$A$101,0)),"")) | J9: =IF($AL9="","",IFERROR(INDEX(Product_Registry!$J$2:$J$101,MATCH($AL9,Product_Registry!$A$2:$A$101,0)),"")) | K9: =IF($AL9="","",IFERROR(INDEX(Product_Registry!$K$2:$K$101,MATCH($AL9,Product_Registry!$A$2:$A$101,0)),"")) | L9: =IF($AL9="","",IFERROR(INDEX(Product_Registry!$L$2:$L$101,MATCH($AL9,Product_Registry!$A$2:$A$101,0)),"")) | M9: =IF($AL9="","",IFERROR(INDEX(Product_Registry!$M$2:$M$101,MATCH($AL9,Product_Registry!$A$2:$A$101,0)),"")) | N9: =IF($AL9="","",$E9+SUMIFS('Logic & Lists'!$E$4:$E$200,'Logic & Lists'!$A$4:$A$200,$AK9,'Logic & Lists'!$C$4:$C$200,"Level 1 Schedule")) | O9: =IF($AL9="","",$P9+SUMIFS('Logic & Lists'!$E$4:$E$200,'Logic & Lists'!$A$4:$A$200,$AK9,'Logic & Lists'!$C$4:$C$200,"Input Frozen")) | P9: =IF($AL9="","",$Q9+SUMIFS('Logic & Lists'!$E$4:$E$200,'Logic & Lists'!$A$4:$A$200,$AK9,'Logic & Lists'!$C$4:$C$200,"Drawing Approval")) | Q9: =IF($AL9="","",$S9+SUMIFS('Logic & Lists'!$E$4:$E$200,'Logic & Lists'!$A$4:$A$200,$AK9,'Logic & Lists'!$C$4:$C$200,"BOM Pass to PR")) | R9: =IF($AL9="","",$S9+SUMIFS('Logic & Lists'!$E$4:$E$200,'Logic & Lists'!$A$4:$A$200,$AK9,'Logic & Lists'!$C$4:$C$200,"PR Schedule")) | S9: =IF($AL9="","",$T9+SUMIFS('Logic & Lists'!$E$4:$E$200,'Logic & Lists'!$A$4:$A$200,$AK9,'Logic & Lists'!$C$4:$C$200,"Components PO Plan")) | T9: =IF($AL9="","",$U9+SUMIFS('Logic & Lists'!$E$4:$E$200,'Logic & Lists'!$A$4:$A$200,$AK9,'Logic & Lists'!$C$4:$C$200,"Production Start")) | U9: =IF($AL9="","",$W9+SUMIFS('Logic & Lists'!$E$4:$E$200,'Logic & Lists'!$A$4:$A$200,$AK9,'Logic & Lists'!$C$4:$C$200,"Production Complete")) | V9: =IF($AL9="","",$Y9+SUMIFS('Logic & Lists'!$E$4:$E$200,'Logic & Lists'!$A$4:$A$200,$AK9,'Logic & Lists'!$C$4:$C$200,"NOI Date")) | W9: =IF($AL9="","",$X9+SUMIFS('Logic & Lists'!$E$4:$E$200,'Logic & Lists'!$A$4:$A$200,$AK9,'Logic & Lists'!$C$4:$C$200,"Internal Test Start")) | X9: =IF($AL9="","",$Y9+SUMIFS('Logic & Lists'!$E$4:$E$200,'Logic & Lists'!$A$4:$A$200,$AK9,'Logic & Lists'!$C$4:$C$200,"Internal Test Complete")) | Y9: =IF($AL9="","",$AA9+SUMIFS('Logic & Lists'!$E$4:$E$200,'Logic & Lists'!$A$4:$A$200,$AK9,'Logic & Lists'!$C$4:$C$200,"FAT Start")) | Z9: =IF($AL9="","",$Y9+SUMIFS('Logic & Lists'!$E$4:$E$200,'Logic & Lists'!$A$4:$A$200,$AK9,'Logic & Lists'!$C$4:$C$200,"FAT Complete")) | AA9: =IF($AL9="","",$F9+SUMIFS('Logic & Lists'!$E$4:$E$200,'Logic & Lists'!$A$4:$A$200,$AK9,'Logic & Lists'!$C$4:$C$200,"Delivery")) | AH9: =IF($AL9="","",IF($AI9<0,"At Risk",IF($AI9<=30,"Watch","On Track"))) | AI9: =IF($F9="","",$F9-TODAY()) | AK9: =IF($AL9="","",IF(COUNTIF('Logic & Lists'!$A$4:$A$200,$C9)>0,$C9,"Default")) | AL9: =IF($A9<>"",$A9,IF($B9<>"",IFERROR(INDEX(Product_Registry!$A$2:$A$101,MATCH($B9,Product_Registry!$B$2:$B$101,0)),IFERROR(INDEX(Product_Registry!$A$2:$A$101,MATCH("*"&$B9&"*",Product_Registry!$B$2:$B$101,0)),"")),"")) | AM9: =IF($AL9="","",IFERROR(INDEX(Product_Registry!$B$2:$B$101,MATCH($AL9,Product_Registry!$A$2:$A$101,0)),""))
C10: =IF($AL10="","",IFERROR(INDEX(Product_Registry!$C$2:$C$101,MATCH($AL10,Product_Registry!$A$2:$A$101,0)),"")) | D10: =IF($AL10="","",IFERROR(INDEX(Product_Registry!$D$2:$D$101,MATCH($AL10,Product_Registry!$A$2:$A$101,0)),"")) | E10: =IF($AL10="","",IFERROR(INDEX(Product_Registry!$E$2:$E$101,MATCH($AL10,Product_Registry!$A$2:$A$101,0)),"")) | F10: =IF($AL10="","",IFERROR(INDEX(Product_Registry!$F$2:$F$101,MATCH($AL10,Product_Registry!$A$2:$A$101,0)),"")) | G10: =IF($AL10="","",IFERROR(INDEX(Product_Registry!$G$2:$G$101,MATCH($AL10,Product_Registry!$A$2:$A$101,0)),"")) | H10: =IF($AL10="","",IFERROR(INDEX(Product_Registry!$H$2:$H$101,MATCH($AL10,Product_Registry!$A$2:$A$101,0)),"")) | I10: =IF($AL10="","",IFERROR(INDEX(Product_Registry!$I$2:$I$101,MATCH($AL10,Product_Registry!$A$2:$A$101,0)),"")) | J10: =IF($AL10="","",IFERROR(INDEX(Product_Registry!$J$2:$J$101,MATCH($AL10,Product_Registry!$A$2:$A$101,0)),"")) | K10: =IF($AL10="","",IFERROR(INDEX(Product_Registry!$K$2:$K$101,MATCH($AL10,Product_Registry!$A$2:$A$101,0)),"")) | L10: =IF($AL10="","",IFERROR(INDEX(Product_Registry!$L$2:$L$101,MATCH($AL10,Product_Registry!$A$2:$A$101,0)),"")) | M10: =IF($AL10="","",IFERROR(INDEX(Product_Registry!$M$2:$M$101,MATCH($AL10,Product_Registry!$A$2:$A$101,0)),"")) | N10: =IF($AL10="","",$E10+SUMIFS('Logic & Lists'!$E$4:$E$200,'Logic & Lists'!$A$4:$A$200,$AK10,'Logic & Lists'!$C$4:$C$200,"Level 1 Schedule")) | O10: =IF($AL10="","",$P10+SUMIFS('Logic & Lists'!$E$4:$E$200,'Logic & Lists'!$A$4:$A$200,$AK10,'Logic & Lists'!$C$4:$C$200,"Input Frozen")) | P10: =IF($AL10="","",$Q10+SUMIFS('Logic & Lists'!$E$4:$E$200,'Logic & Lists'!$A$4:$A$200,$AK10,'Logic & Lists'!$C$4:$C$200,"Drawing Approval")) | Q10: =IF($AL10="","",$S10+SUMIFS('Logic & Lists'!$E$4:$E$200,'Logic & Lists'!$A$4:$A$200,$AK10,'Logic & Lists'!$C$4:$C$200,"BOM Pass to PR")) | R10: =IF($AL10="","",$S10+SUMIFS('Logic & Lists'!$E$4:$E$200,'Logic & Lists'!$A$4:$A$200,$AK10,'Logic & Lists'!$C$4:$C$200,"PR Schedule")) | S10: =IF($AL10="","",$T10+SUMIFS('Logic & Lists'!$E$4:$E$200,'Logic & Lists'!$A$4:$A$200,$AK10,'Logic & Lists'!$C$4:$C$200,"Components PO Plan")) | T10: =IF($AL10="","",$U10+SUMIFS('Logic & Lists'!$E$4:$E$200,'Logic & Lists'!$A$4:$A$200,$AK10,'Logic & Lists'!$C$4:$C$200,"Production Start")) | U10: =IF($AL10="","",$W10+SUMIFS('Logic & Lists'!$E$4:$E$200,'Logic & Lists'!$A$4:$A$200,$AK10,'Logic & Lists'!$C$4:$C$200,"Production Complete")) | V10: =IF($AL10="","",$Y10+SUMIFS('Logic & Lists'!$E$4:$E$200,'Logic & Lists'!$A$4:$A$200,$AK10,'Logic & Lists'!$C$4:$C$200,"NOI Date")) | W10: =IF($AL10="","",$X10+SUMIFS('Logic & Lists'!$E$4:$E$200,'Logic & Lists'!$A$4:$A$200,$AK10,'Logic & Lists'!$C$4:$C$200,"Internal Test Start")) | X10: =IF($AL10="","",$Y10+SUMIFS('Logic & Lists'!$E$4:$E$200,'Logic & Lists'!$A$4:$A$200,$AK10,'Logic & Lists'!$C$4:$C$200,"Internal Test Complete")) | Y10: =IF($AL10="","",$AA10+SUMIFS('Logic & Lists'!$E$4:$E$200,'Logic & Lists'!$A$4:$A$200,$AK10,'Logic & Lists'!$C$4:$C$200,"FAT Start")) | Z10: =IF($AL10="","",$Y10+SUMIFS('Logic & Lists'!$E$4:$E$200,'Logic & Lists'!$A$4:$A$200,$AK10,'Logic & Lists'!$C$4:$C$200,"FAT Complete")) | AA10: =IF($AL10="","",$F10+SUMIFS('Logic & Lists'!$E$4:$E$200,'Logic & Lists'!$A$4:$A$200,$AK10,'Logic & Lists'!$C$4:$C$200,"Delivery")) | AH10: =IF($AL10="","",IF($AI10<0,"At Risk",IF($AI10<=30,"Watch","On Track"))) | AI10: =IF($F10="","",$F10-TODAY()) | AK10: =IF($AL10="","",IF(COUNTIF('Logic & Lists'!$A$4:$A$200,$C10)>0,$C10,"Default")) | AL10: =IF($A10<>"",$A10,IF($B10<>"",IFERROR(INDEX(Product_Registry!$A$2:$A$101,MATCH($B10,Product_Registry!$B$2:$B$101,0)),IFERROR(INDEX(Product_Registry!$A$2:$A$101,MATCH("*"&$B10&"*",Product_Registry!$B$2:$B$101,0)),"")),"")) | AM10: =IF($AL10="","",IFERROR(INDEX(Product_Registry!$B$2:$B$101,MATCH($AL10,Product_Registry!$A$2:$A$101,0)),""))
C11: =IF($AL11="","",IFERROR(INDEX(Product_Registry!$C$2:$C$101,MATCH($AL11,Product_Registry!$A$2:$A$101,0)),"")) | D11: =IF($AL11="","",IFERROR(INDEX(Product_Registry!$D$2:$D$101,MATCH($AL11,Product_Registry!$A$2:$A$101,0)),"")) | E11: =IF($AL11="","",IFERROR(INDEX(Product_Registry!$E$2:$E$101,MATCH($AL11,Product_Registry!$A$2:$A$101,0)),"")) | F11: =IF($AL11="","",IFERROR(INDEX(Product_Registry!$F$2:$F$101,MATCH($AL11,Product_Registry!$A$2:$A$101,0)),"")) | G11: =IF($AL11="","",IFERROR(INDEX(Product_Registry!$G$2:$G$101,MATCH($AL11,Product_Registry!$A$2:$A$101,0)),"")) | H11: =IF($AL11="","",IFERROR(INDEX(Product_Registry!$H$2:$H$101,MATCH($AL11,Product_Registry!$A$2:$A$101,0)),"")) | I11: =IF($AL11="","",IFERROR(INDEX(Product_Registry!$I$2:$I$101,MATCH($AL11,Product_Registry!$A$2:$A$101,0)),"")) | J11: =IF($AL11="","",IFERROR(INDEX(Product_Registry!$J$2:$J$101,MATCH($AL11,Product_Registry!$A$2:$A$101,0)),"")) | K11: =IF($AL11="","",IFERROR(INDEX(Product_Registry!$K$2:$K$101,MATCH($AL11,Product_Registry!$A$2:$A$101,0)),"")) | L11: =IF($AL11="","",IFERROR(INDEX(Product_Registry!$L$2:$L$101,MATCH($AL11,Product_Registry!$A$2:$A$101,0)),"")) | M11: =IF($AL11="","",IFERROR(INDEX(Product_Registry!$M$2:$M$101,MATCH($AL11,Product_Registry!$A$2:$A$101,0)),"")) | N11: =IF($AL11="","",$E11+SUMIFS('Logic & Lists'!$E$4:$E$200,'Logic & Lists'!$A$4:$A$200,$AK11,'Logic & Lists'!$C$4:$C$200,"Level 1 Schedule")) | O11: =IF($AL11="","",$P11+SUMIFS('Logic & Lists'!$E$4:$E$200,'Logic & Lists'!$A$4:$A$200,$AK11,'Logic & Lists'!$C$4:$C$200,"Input Frozen")) | P11: =IF($AL11="","",$Q11+SUMIFS('Logic & Lists'!$E$4:$E$200,'Logic & Lists'!$A$4:$A$200,$AK11,'Logic & Lists'!$C$4:$C$200,"Drawing Approval")) | Q11: =IF($AL11="","",$S11+SUMIFS('Logic & Lists'!$E$4:$E$200,'Logic & Lists'!$A$4:$A$200,$AK11,'Logic & Lists'!$C$4:$C$200,"BOM Pass to PR")) | R11: =IF($AL11="","",$S11+SUMIFS('Logic & Lists'!$E$4:$E$200,'Logic & Lists'!$A$4:$A$200,$AK11,'Logic & Lists'!$C$4:$C$200,"PR Schedule")) | S11: =IF($AL11="","",$T11+SUMIFS('Logic & Lists'!$E$4:$E$200,'Logic & Lists'!$A$4:$A$200,$AK11,'Logic & Lists'!$C$4:$C$200,"Components PO Plan")) | T11: =IF($AL11="","",$U11+SUMIFS('Logic & Lists'!$E$4:$E$200,'Logic & Lists'!$A$4:$A$200,$AK11,'Logic & Lists'!$C$4:$C$200,"Production Start")) | U11: =IF($AL11="","",$W11+SUMIFS('Logic & Lists'!$E$4:$E$200,'Logic & Lists'!$A$4:$A$200,$AK11,'Logic & Lists'!$C$4:$C$200,"Production Complete")) | V11: =IF($AL11="","",$Y11+SUMIFS('Logic & Lists'!$E$4:$E$200,'Logic & Lists'!$A$4:$A$200,$AK11,'Logic & Lists'!$C$4:$C$200,"NOI Date")) | W11: =IF($AL11="","",$X11+SUMIFS('Logic & Lists'!$E$4:$E$200,'Logic & Lists'!$A$4:$A$200,$AK11,'Logic & Lists'!$C$4:$C$200,"Internal Test Start")) | X11: =IF($AL11="","",$Y11+SUMIFS('Logic & Lists'!$E$4:$E$200,'Logic & Lists'!$A$4:$A$200,$AK11,'Logic & Lists'!$C$4:$C$200,"Internal Test Complete")) | Y11: =IF($AL11="","",$AA11+SUMIFS('Logic & Lists'!$E$4:$E$200,'Logic & Lists'!$A$4:$A$200,$AK11,'Logic & Lists'!$C$4:$C$200,"FAT Start")) | Z11: =IF($AL11="","",$Y11+SUMIFS('Logic & Lists'!$E$4:$E$200,'Logic & Lists'!$A$4:$A$200,$AK11,'Logic & Lists'!$C$4:$C$200,"FAT Complete")) | AA11: =IF($AL11="","",$F11+SUMIFS('Logic & Lists'!$E$4:$E$200,'Logic & Lists'!$A$4:$A$200,$AK11,'Logic & Lists'!$C$4:$C$200,"Delivery")) | AH11: =IF($AL11="","",IF($AI11<0,"At Risk",IF($AI11<=30,"Watch","On Track"))) | AI11: =IF($F11="","",$F11-TODAY()) | AK11: =IF($AL11="","",IF(COUNTIF('Logic & Lists'!$A$4:$A$200,$C11)>0,$C11,"Default")) | AL11: =IF($A11<>"",$A11,IF($B11<>"",IFERROR(INDEX(Product_Registry!$A$2:$A$101,MATCH($B11,Product_Registry!$B$2:$B$101,0)),IFERROR(INDEX(Product_Registry!$A$2:$A$101,MATCH("*"&$B11&"*",Product_Registry!$B$2:$B$101,0)),"")),"")) | AM11: =IF($AL11="","",IFERROR(INDEX(Product_Registry!$B$2:$B$101,MATCH($AL11,Product_Registry!$A$2:$A$101,0)),""))
C12: =IF($AL12="","",IFERROR(INDEX(Product_Registry!$C$2:$C$101,MATCH($AL12,Product_Registry!$A$2:$A$101,0)),"")) | D12: =IF($AL12="","",IFERROR(INDEX(Product_Registry!$D$2:$D$101,MATCH($AL12,Product_Registry!$A$2:$A$101,0)),"")) | E12: =IF($AL12="","",IFERROR(INDEX(Product_Registry!$E$2:$E$101,MATCH($AL12,Product_Registry!$A$2:$A$101,0)),"")) | F12: =IF($AL12="","",IFERROR(INDEX(Product_Registry!$F$2:$F$101,MATCH($AL12,Product_Registry!$A$2:$A$101,0)),"")) | G12: =IF($AL12="","",IFERROR(INDEX(Product_Registry!$G$2:$G$101,MATCH($AL12,Product_Registry!$A$2:$A$101,0)),"")) | H12: =IF($AL12="","",IFERROR(INDEX(Product_Registry!$H$2:$H$101,MATCH($AL12,Product_Registry!$A$2:$A$101,0)),"")) | I12: =IF($AL12="","",IFERROR(INDEX(Product_Registry!$I$2:$I$101,MATCH($AL12,Product_Registry!$A$2:$A$101,0)),"")) | J12: =IF($AL12="","",IFERROR(INDEX(Product_Registry!$J$2:$J$101,MATCH($AL12,Product_Registry!$A$2:$A$101,0)),"")) | K12: =IF($AL12="","",IFERROR(INDEX(Product_Registry!$K$2:$K$101,MATCH($AL12,Product_Registry!$A$2:$A$101,0)),"")) | L12: =IF($AL12="","",IFERROR(INDEX(Product_Registry!$L$2:$L$101,MATCH($AL12,Product_Registry!$A$2:$A$101,0)),"")) | M12: =IF($AL12="","",IFERROR(INDEX(Product_Registry!$M$2:$M$101,MATCH($AL12,Product_Registry!$A$2:$A$101,0)),"")) | N12: =IF($AL12="","",$E12+SUMIFS('Logic & Lists'!$E$4:$E$200,'Logic & Lists'!$A$4:$A$200,$AK12,'Logic & Lists'!$C$4:$C$200,"Level 1 Schedule")) | O12: =IF($AL12="","",$P12+SUMIFS('Logic & Lists'!$E$4:$E$200,'Logic & Lists'!$A$4:$A$200,$AK12,'Logic & Lists'!$C$4:$C$200,"Input Frozen")) | P12: =IF($AL12="","",$Q12+SUMIFS('Logic & Lists'!$E$4:$E$200,'Logic & Lists'!$A$4:$A$200,$AK12,'Logic & Lists'!$C$4:$C$200,"Drawing Approval")) | Q12: =IF($AL12="","",$S12+SUMIFS('Logic & Lists'!$E$4:$E$200,'Logic & Lists'!$A$4:$A$200,$AK12,'Logic & Lists'!$C$4:$C$200,"BOM Pass to PR")) | R12: =IF($AL12="","",$S12+SUMIFS('Logic & Lists'!$E$4:$E$200,'Logic & Lists'!$A$4:$A$200,$AK12,'Logic & Lists'!$C$4:$C$200,"PR Schedule")) | S12: =IF($AL12="","",$T12+SUMIFS('Logic & Lists'!$E$4:$E$200,'Logic & Lists'!$A$4:$A$200,$AK12,'Logic & Lists'!$C$4:$C$200,"Components PO Plan")) | T12: =IF($AL12="","",$U12+SUMIFS('Logic & Lists'!$E$4:$E$200,'Logic & Lists'!$A$4:$A$200,$AK12,'Logic & Lists'!$C$4:$C$200,"Production Start")) | U12: =IF($AL12="","",$W12+SUMIFS('Logic & Lists'!$E$4:$E$200,'Logic & Lists'!$A$4:$A$200,$AK12,'Logic & Lists'!$C$4:$C$200,"Production Complete")) | V12: =IF($AL12="","",$Y12+SUMIFS('Logic & Lists'!$E$4:$E$200,'Logic & Lists'!$A$4:$A$200,$AK12,'Logic & Lists'!$C$4:$C$200,"NOI Date")) | W12: =IF($AL12="","",$X12+SUMIFS('Logic & Lists'!$E$4:$E$200,'Logic & Lists'!$A$4:$A$200,$AK12,'Logic & Lists'!$C$4:$C$200,"Internal Test Start")) | X12: =IF($AL12="","",$Y12+SUMIFS('Logic & Lists'!$E$4:$E$200,'Logic & Lists'!$A$4:$A$200,$AK12,'Logic & Lists'!$C$4:$C$200,"Internal Test Complete")) | Y12: =IF($AL12="","",$AA12+SUMIFS('Logic & Lists'!$E$4:$E$200,'Logic & Lists'!$A$4:$A$200,$AK12,'Logic & Lists'!$C$4:$C$200,"FAT Start")) | Z12: =IF($AL12="","",$Y12+SUMIFS('Logic & Lists'!$E$4:$E$200,'Logic & Lists'!$A$4:$A$200,$AK12,'Logic & Lists'!$C$4:$C$200,"FAT Complete")) | AA12: =IF($AL12="","",$F12+SUMIFS('Logic & Lists'!$E$4:$E$200,'Logic & Lists'!$A$4:$A$200,$AK12,'Logic & Lists'!$C$4:$C$200,"Delivery")) | AH12: =IF($AL12="","",IF($AI12<0,"At Risk",IF($AI12<=30,"Watch","On Track"))) | AI12: =IF($F12="","",$F12-TODAY()) | AK12: =IF($AL12="","",IF(COUNTIF('Logic & Lists'!$A$4:$A$200,$C12)>0,$C12,"Default")) | AL12: =IF($A12<>"",$A12,IF($B12<>"",IFERROR(INDEX(Product_Registry!$A$2:$A$101,MATCH($B12,Product_Registry!$B$2:$B$101,0)),IFERROR(INDEX(Product_Registry!$A$2:$A$101,MATCH("*"&$B12&"*",Product_Registry!$B$2:$B$101,0)),"")),"")) | AM12: =IF($AL12="","",IFERROR(INDEX(Product_Registry!$B$2:$B$101,MATCH($AL12,Product_Registry!$A$2:$A$101,0)),""))
C13: =IF($AL13="","",IFERROR(INDEX(Product_Registry!$C$2:$C$101,MATCH($AL13,Product_Registry!$A$2:$A$101,0)),"")) | D13: =IF($AL13="","",IFERROR(INDEX(Product_Registry!$D$2:$D$101,MATCH($AL13,Product_Registry!$A$2:$A$101,0)),"")) | E13: =IF($AL13="","",IFERROR(INDEX(Product_Registry!$E$2:$E$101,MATCH($AL13,Product_Registry!$A$2:$A$101,0)),"")) | F13: =IF($AL13="","",IFERROR(INDEX(Product_Registry!$F$2:$F$101,MATCH($AL13,Product_Registry!$A$2:$A$101,0)),"")) | G13: =IF($AL13="","",IFERROR(INDEX(Product_Registry!$G$2:$G$101,MATCH($AL13,Product_Registry!$A$2:$A$101,0)),"")) | H13: =IF($AL13="","",IFERROR(INDEX(Product_Registry!$H$2:$H$101,MATCH($AL13,Product_Registry!$A$2:$A$101,0)),"")) | I13: =IF($AL13="","",IFERROR(INDEX(Product_Registry!$I$2:$I$101,MATCH($AL13,Product_Registry!$A$2:$A$101,0)),"")) | J13: =IF($AL13="","",IFERROR(INDEX(Product_Registry!$J$2:$J$101,MATCH($AL13,Product_Registry!$A$2:$A$101,0)),"")) | K13: =IF($AL13="","",IFERROR(INDEX(Product_Registry!$K$2:$K$101,MATCH($AL13,Product_Registry!$A$2:$A$101,0)),"")) | L13: =IF($AL13="","",IFERROR(INDEX(Product_Registry!$L$2:$L$101,MATCH($AL13,Product_Registry!$A$2:$A$101,0)),"")) | M13: =IF($AL13="","",IFERROR(INDEX(Product_Registry!$M$2:$M$101,MATCH($AL13,Product_Registry!$A$2:$A$101,0)),"")) | N13: =IF($AL13="","",$E13+SUMIFS('Logic & Lists'!$E$4:$E$200,'Logic & Lists'!$A$4:$A$200,$AK13,'Logic & Lists'!$C$4:$C$200,"Level 1 Schedule")) | O13: =IF($AL13="","",$P13+SUMIFS('Logic & Lists'!$E$4:$E$200,'Logic & Lists'!$A$4:$A$200,$AK13,'Logic & Lists'!$C$4:$C$200,"Input Frozen")) | P13: =IF($AL13="","",$Q13+SUMIFS('Logic & Lists'!$E$4:$E$200,'Logic & Lists'!$A$4:$A$200,$AK13,'Logic & Lists'!$C$4:$C$200,"Drawing Approval")) | Q13: =IF($AL13="","",$S13+SUMIFS('Logic & Lists'!$E$4:$E$200,'Logic & Lists'!$A$4:$A$200,$AK13,'Logic & Lists'!$C$4:$C$200,"BOM Pass to PR")) | R13: =IF($AL13="","",$S13+SUMIFS('Logic & Lists'!$E$4:$E$200,'Logic & Lists'!$A$4:$A$200,$AK13,'Logic & Lists'!$C$4:$C$200,"PR Schedule")) | S13: =IF($AL13="","",$T13+SUMIFS('Logic & Lists'!$E$4:$E$200,'Logic & Lists'!$A$4:$A$200,$AK13,'Logic & Lists'!$C$4:$C$200,"Components PO Plan")) | T13: =IF($AL13="","",$U13+SUMIFS('Logic & Lists'!$E$4:$E$200,'Logic & Lists'!$A$4:$A$200,$AK13,'Logic & Lists'!$C$4:$C$200,"Production Start")) | U13: =IF($AL13="","",$W13+SUMIFS('Logic & Lists'!$E$4:$E$200,'Logic & Lists'!$A$4:$A$200,$AK13,'Logic & Lists'!$C$4:$C$200,"Production Complete")) | V13: =IF($AL13="","",$Y13+SUMIFS('Logic & Lists'!$E$4:$E$200,'Logic & Lists'!$A$4:$A$200,$AK13,'Logic & Lists'!$C$4:$C$200,"NOI Date")) | W13: =IF($AL13="","",$X13+SUMIFS('Logic & Lists'!$E$4:$E$200,'Logic & Lists'!$A$4:$A$200,$AK13,'Logic & Lists'!$C$4:$C$200,"Internal Test Start")) | X13: =IF($AL13="","",$Y13+SUMIFS('Logic & Lists'!$E$4:$E$200,'Logic & Lists'!$A$4:$A$200,$AK13,'Logic & Lists'!$C$4:$C$200,"Internal Test Complete")) | Y13: =IF($AL13="","",$AA13+SUMIFS('Logic & Lists'!$E$4:$E$200,'Logic & Lists'!$A$4:$A$200,$AK13,'Logic & Lists'!$C$4:$C$200,"FAT Start")) | Z13: =IF($AL13="","",$Y13+SUMIFS('Logic & Lists'!$E$4:$E$200,'Logic & Lists'!$A$4:$A$200,$AK13,'Logic & Lists'!$C$4:$C$200,"FAT Complete")) | AA13: =IF($AL13="","",$F13+SUMIFS('Logic & Lists'!$E$4:$E$200,'Logic & Lists'!$A$4:$A$200,$AK13,'Logic & Lists'!$C$4:$C$200,"Delivery")) | AH13: =IF($AL13="","",IF($AI13<0,"At Risk",IF($AI13<=30,"Watch","On Track"))) | AI13: =IF($F13="","",$F13-TODAY()) | AK13: =IF($AL13="","",IF(COUNTIF('Logic & Lists'!$A$4:$A$200,$C13)>0,$C13,"Default")) | AL13: =IF($A13<>"",$A13,IF($B13<>"",IFERROR(INDEX(Product_Registry!$A$2:$A$101,MATCH($B13,Product_Registry!$B$2:$B$101,0)),IFERROR(INDEX(Product_Registry!$A$2:$A$101,MATCH("*"&$B13&"*",Product_Registry!$B$2:$B$101,0)),"")),"")) | AM13: =IF($AL13="","",IFERROR(INDEX(Product_Registry!$B$2:$B$101,MATCH($AL13,Product_Registry!$A$2:$A$101,0)),""))
